<?xml version="1.0" ?>
<!-- =================================================================================== -->
<!-- |    This document was autogenerated by xacro from src/urdf_xacro_gazebo/urdf/xacro/car.xacro | -->
<!-- |    EDITING THIS FILE BY HAND IS NOT RECOMMENDED                                 | -->
<!-- =================================================================================== -->
<robot name="car">
  <link name="base_footprint">
    <visual>
      <geometry>
        <sphere radius="0.001"/>
      </geometry>
    </visual>
  </link>
  <!-- 底盘 -->
  <link name="base_link">
    <visual>
      <geometry>
        <cylinder length="0.08" radius="0.15"/>
      </geometry>
      <origin rpy="0 0 0" xyz="0 0 0"/>
      <material name="base_link_color">
        <color rgba="0 0 1.0 0.5"/>
      </material>
    </visual>
    <collision>
      <geometry>
        <cylinder length="0.08" radius="0.15"/>
      </geometry>
      <origin rpy="0 0 0" xyz="0 0 0"/>
    </collision>
    <inertial>
      <mass value="2"/>
      <inertia ixx="0.012316666666666665" ixy="0" ixz="0" iyy="0.012316666666666665" iyz="0" izz="0.0225"/>
    </inertial>
  </link>
  <gazebo reference="base_link">
    <material>Gazebo/Yellow</material>
  </gazebo>
  <joint name="link2foorprint" type="fixed">
    <parent link="base_footprint"/>
    <child link="base_link"/>
    <origin rpy="0 0 0" xyz="0 0 0.055"/>
  </joint>
  <!-- 左/右旋转轮 -->
  <link name="left_wheel">
    <visual>
      <geometry>
        <cylinder length="0.015" radius="0.0325"/>
      </geometry>
      <origin rpy="1.5707963 0 0" xyz="0 0 0"/>
      <material name="black">
        <color rgba="0 0 0 0.3"/>
      </material>
    </visual>
    <collision>
      <geometry>
        <cylinder length="0.015" radius="0.0325"/>
      </geometry>
      <origin rpy="1.5707963 0 0" xyz="0 0 0"/>
    </collision>
    <inertial>
      <mass value="0.05"/>
      <inertia ixx="1.4140625000000002e-05" ixy="0" ixz="0" iyy="1.4140625000000002e-05" iyz="0" izz="2.6406250000000005e-05"/>
    </inertial>
  </link>
  <gazebo reference="left_wheel">
    <material>Gazebo/Red</material>
  </gazebo>
  <joint name="left2link" type="continuous">
    <parent link="base_link"/>
    <child link="left_wheel"/>
    <origin rpy="0 0 0" xyz="0 0.1575 -0.0225"/>
    <axis xyz="0 1 0"/>
  </joint>
  <link name="right_wheel">
    <visual>
      <geometry>
        <cylinder length="0.015" radius="0.0325"/>
      </geometry>
      <origin rpy="1.5707963 0 0" xyz="0 0 0"/>
      <material name="black">
        <color rgba="0 0 0 0.3"/>
      </material>
    </visual>
    <collision>
      <geometry>
        <cylinder length="0.015" radius="0.0325"/>
      </geometry>
      <origin rpy="1.5707963 0 0" xyz="0 0 0"/>
    </collision>
    <inertial>
      <mass value="0.05"/>
      <inertia ixx="1.4140625000000002e-05" ixy="0" ixz="0" iyy="1.4140625000000002e-05" iyz="0" izz="2.6406250000000005e-05"/>
    </inertial>
  </link>
  <gazebo reference="right_wheel">
    <material>Gazebo/Red</material>
  </gazebo>
  <joint name="right2link" type="continuous">
    <parent link="base_link"/>
    <child link="right_wheel"/>
    <origin rpy="0 0 0" xyz="0 -0.1575 -0.0225"/>
    <axis xyz="0 1 0"/>
  </joint>
  <link name="front_wheel">
    <visual>
      <geometry>
        <sphere radius="0.0075"/>
      </geometry>
      <origin rpy="0 0 0" xyz="0 0 0"/>
      <material name="wheel_color">
        <color rgba="0 0 0 0.3"/>
      </material>
    </visual>
    <collision>
      <geometry>
        <sphere radius="0.0075"/>
      </geometry>
      <origin rpy="0 0 0" xyz="0 0 0"/>
    </collision>
    <inertial>
      <mass value="0.01"/>
      <inertia ixx="2.2499999999999996e-07" ixy="0" ixz="0" iyy="2.2499999999999996e-07" iyz="0" izz="2.2499999999999996e-07"/>
    </inertial>
  </link>
  <gazebo reference="front_wheel">
    <material>Gazebo/Red</material>
  </gazebo>
  <joint name="front2link" type="continuous">
    <parent link="base_link"/>
    <child link="front_wheel"/>
    <origin rpy="0 0 0" xyz="0.12 0 -0.0475"/>
    <axis xyz="0 1 0"/>
  </joint>
  <link name="back_wheel">
    <visual>
      <geometry>
        <sphere radius="0.0075"/>
      </geometry>
      <origin rpy="0 0 0" xyz="0 0 0"/>
      <material name="wheel_color">
        <color rgba="0 0 0 0.3"/>
      </material>
    </visual>
    <collision>
      <geometry>
        <sphere radius="0.0075"/>
      </geometry>
      <origin rpy="0 0 0" xyz="0 0 0"/>
    </collision>
    <inertial>
      <mass value="0.01"/>
      <inertia ixx="2.2499999999999996e-07" ixy="0" ixz="0" iyy="2.2499999999999996e-07" iyz="0" izz="2.2499999999999996e-07"/>
    </inertial>
  </link>
  <gazebo reference="back_wheel">
    <material>Gazebo/Red</material>
  </gazebo>
  <joint name="back2link" type="continuous">
    <parent link="base_link"/>
    <child link="back_wheel"/>
    <origin rpy="0 0 0" xyz="-0.12 0 -0.0475"/>
    <axis xyz="0 1 0"/>
  </joint>
  <!-- z方向 -->
  <link name="camera">
    <visual>
      <geometry>
        <box size="0.02 0.02 0.02"/>
      </geometry>
      <origin rpy="0 0 0" xyz="0 0 0"/>
      <material name="black">
        <color rgb="0 0 0 0.4"/>
      </material>
    </visual>
    <collision>
      <geometry>
        <box size="0.02 0.02 0.02"/>
      </geometry>
      <origin rpy="0 0 0" xyz="0 0 0"/>
    </collision>
    <inertial>
      <mass value="0.01"/>
      <inertia ixx="6.666666666666668e-07" ixy="0" ixz="0" iyy="6.666666666666668e-07" iyz="0" izz="6.666666666666668e-07"/>
    </inertial>
  </link>
  <gazebo reference="camera">
    <material>Gazebo/Blue</material>
  </gazebo>
  <joint name="camera2base" type="fixed">
    <parent link="base_link"/>
    <child link="camera"/>
    <origin rpy="0 0 0" xyz="0.12 0 0.05"/>
  </joint>
  <link name="stick">
    <visual>
      <geometry>
        <cylinder length="0.15" radius="0.01"/>
      </geometry>
      <material name="yellow">
        <color rgba="0.8 0.5 0 0.5"/>
      </material>
    </visual>
    <collision>
      <geometry>
        <cylinder length="0.15" radius="0.01"/>
      </geometry>
      <origin rpy="0 0 0" xyz="0 0 0"/>
    </collision>
    <inertial>
      <mass value="0.1"/>
      <inertia ixx="0.00019000000000000004" ixy="0" ixz="0" iyy="0.00019000000000000004" iyz="0" izz="5e-06"/>
    </inertial>
  </link>
  <gazebo reference="stick">
    <material>Gazebo/Gray</material>
  </gazebo>
  <joint name="stick2base" type="fixed">
    <parent link="base_link"/>
    <child link="stick"/>
    <origin rpy="0 0 0" xyz="0 0 0.11499999999999999"/>
  </joint>
  <link name="laser">
    <visual>
      <geometry>
        <cylinder length="0.05" radius="0.03"/>
      </geometry>
      <material name="black">
        <color rgba="0.8 0.5 0 0.5"/>
      </material>
    </visual>
    <collision>
      <geometry>
        <cylinder length="0.05" radius="0.03"/>
      </geometry>
      <origin rpy="0 0 0" xyz="0 0 0"/>
    </collision>
    <inertial>
      <mass value="0.15"/>
      <inertia ixx="6.5e-05" ixy="0" ixz="0" iyy="6.5e-05" iyz="0" izz="6.749999999999999e-05"/>
    </inertial>
  </link>
  <gazebo reference="laser">
    <material>Gazebo/Black</material>
  </gazebo>
  <joint name="laser2stick" type="fixed">
    <parent link="stick"/>
    <child link="laser"/>
    <origin rpy="0 0 0" xyz="0 0 0.1"/>
  </joint>
  <!-- Transmission is important to link the joints and the controller -->
  <transmission name="left2link_trans">
    <type>transmission_interface/SimpleTransmission</type>
    <joint name="left2link">
      <hardwareInterface>hardware_interface/VelocityJointInterface</hardwareInterface>
    </joint>
    <actuator name="left2link_motor">
      <hardwareInterface>hardware_interface/VelocityJointInterface</hardwareInterface>
      <mechanicalReduction>1</mechanicalReduction>
    </actuator>
  </transmission>
  <!-- Transmission is important to link the joints and the controller -->
  <transmission name="right2link_trans">
    <type>transmission_interface/SimpleTransmission</type>
    <joint name="right2link">
      <hardwareInterface>hardware_interface/VelocityJointInterface</hardwareInterface>
    </joint>
    <actuator name="right2link_motor">
      <hardwareInterface>hardware_interface/VelocityJointInterface</hardwareInterface>
      <mechanicalReduction>1</mechanicalReduction>
    </actuator>
  </transmission>
  <!-- 控制器 -->
  <gazebo>
    <plugin filename="libgazebo_ros_diff_drive.so" name="differential_drive_controller">
      <rosDebugLevel>Debug</rosDebugLevel>
      <publishWheelTF>true</publishWheelTF>
      <robotNamespace>/</robotNamespace>
      <publishTf>1</publishTf>
      <publishWheelJointState>true</publishWheelJointState>
      <alwaysOn>true</alwaysOn>
      <updateRate>100.0</updateRate>
      <legacyMode>true</legacyMode>
      <leftJoint>left2link</leftJoint>
      <!-- 左轮 -->
      <rightJoint>right2link</rightJoint>
      <!-- 右轮 -->
      <wheelSeparation>0.3</wheelSeparation>
      <!-- 车轮间距 -->
      <wheelDiameter>0.065</wheelDiameter>
      <!-- 车轮直径 -->
      <broadcastTF>1</broadcastTF>
      <wheelTorque>30</wheelTorque>
      <wheelAcceleration>1.8</wheelAcceleration>
      <commandTopic>cmd_vel</commandTopic>
      <!-- 运动控制话题 -->
      <odometryFrame>odom</odometryFrame>
      <odometryTopic>odom</odometryTopic>
      <!-- 里程计话题 -->
      <robotBaseFrame>base_footprint</robotBaseFrame>
      <!-- 根坐标系 -->
    </plugin>
  </gazebo>
  <!-- 雷达 -->
  <gazebo reference="laser">
    <sensor name="rplidar" type="ray">
      <pose>0 0 0 0 0 0</pose>
      <visualize>true</visualize>
      <update_rate>5.5</update_rate>
      <ray>
        <scan>
          <horizontal>
            <samples>360</samples>
            <resolution>1</resolution>
            <min_angle>-3</min_angle>
            <max_angle>3</max_angle>
          </horizontal>
        </scan>
        <range>
          <min>0.10</min>
          <max>30.0</max>
          <resolution>0.01</resolution>
        </range>
        <noise>
          <type>gaussian</type>
          <mean>0.0</mean>
          <stddev>0.01</stddev>
        </noise>
      </ray>
      <plugin filename="libgazebo_ros_laser.so" name="gazebo_rplidar">
        <topicName>/scan</topicName>
        <frameName>laser</frameName>
      </plugin>
    </sensor>
  </gazebo>
  <!-- 被引用的link -->
  <gazebo reference="camera">
    <!-- 类型设置为 camara -->
    <sensor name="camera_node" type="camera">
      <update_rate>30.0</update_rate>
      <!-- 更新频率 -->
      <!-- 摄像头基本信息设置 -->
      <camera name="head">
        <horizontal_fov>1.3962634</horizontal_fov>
        <image>
          <width>1280</width>
          <height>720</height>
          <format>R8G8B8</format>
        </image>
        <clip>
          <near>0.02</near>
          <far>300</far>
        </clip>
        <noise>
          <type>gaussian</type>
          <mean>0.0</mean>
          <stddev>0.007</stddev>
        </noise>
      </camera>
      <!-- 核心插件 -->
      <plugin filename="libgazebo_ros_camera.so" name="gazebo_camera">
        <alwaysOn>true</alwaysOn>
        <updateRate>0.0</updateRate>
        <cameraName>/camera</cameraName>
        <imageTopicName>image_raw</imageTopicName>
        <cameraInfoTopicName>camera_info</cameraInfoTopicName>
        <frameName>camera</frameName>
        <hackBaseline>0.07</hackBaseline>
        <distortionK1>0.0</distortionK1>
        <distortionK2>0.0</distortionK2>
        <distortionK3>0.0</distortionK3>
        <distortionT1>0.0</distortionT1>
        <distortionT2>0.0</distortionT2>
      </plugin>
    </sensor>
  </gazebo>
  <gazebo reference="stick">
    <sensor name="camera" type="depth">
      <always_on>true</always_on>
      <update_rate>20.0</update_rate>
      <camera>
        <horizontal_fov>1.0471975333333332</horizontal_fov>
        <image>
          <format>R8G8B8</format>
          <width>640</width>
          <height>480</height>
        </image>
        <clip>
          <near>0.05</near>
          <far>8.0</far>
        </clip>
      </camera>
      <plugin filename="libgazebo_ros_openni_kinect.so" name="kinect_camera_controller">
        <cameraName>camera</cameraName>
        <alwaysOn>true</alwaysOn>
        <updateRate>10</updateRate>
        <imageTopicName>rgb/image_raw</imageTopicName>
        <depthImageTopicName>depth/image_raw</depthImageTopicName>
        <pointCloudTopicName>depth/points</pointCloudTopicName>
        <cameraInfoTopicName>rgb/camera_info</cameraInfoTopicName>
        <depthImageCameraInfoTopicName>depth/camera_info</depthImageCameraInfoTopicName>
        <frameName>stick</frameName>
        <baseline>0.1</baseline>
        <distortion_k1>0.0</distortion_k1>
        <distortion_k2>0.0</distortion_k2>
        <distortion_k3>0.0</distortion_k3>
        <distortion_t1>0.0</distortion_t1>
        <distortion_t2>0.0</distortion_t2>
        <pointCloudCutoff>0.4</pointCloudCutoff>
      </plugin>
    </sensor>
  </gazebo>
</robot>

